/root/src/utils.py:366: RuntimeWarning: divide by zero encountered in power
  r_inv = np.power(rowsum, -1).flatten()
args
 Namespace(batch_size=8, concat=10, conditional=True, cuda=True, dataset='news20', dropout=0.5, epochs=400, hidden=8, lam=1.0, latent_size=10, lr=0.01, num_models=100, pretrain_epochs=8, pretrain_lr=0.01, runs=3, samples=4, seed=42, tem=0.5, update_epochs=20, warmup=200, weight_decay=0.0005)
Hypergraph(num_v=16342, num_e=100)
Run Train:   0%|                                                                                                                                 | 0/3 [00:00<?, ?it/s]Run Train:   0%|                                                                                                                                 | 0/3 [00:01<?, ?it/s]
Traceback (most recent call last):
  File "lahgcn_news.py", line 226, in <module>
    X_list = get_augmented_features(args.concat)
  File "lahgcn_news.py", line 162, in get_augmented_features
    for batch_z, cvae_features_batch in cvae_features_loader:
  File "/usr/local/miniconda3/envs/hy/lib/python3.8/site-packages/torch/utils/data/dataloader.py", line 628, in __next__
    data = self._next_data()
  File "/usr/local/miniconda3/envs/hy/lib/python3.8/site-packages/torch/utils/data/dataloader.py", line 1333, in _next_data
    return self._process_data(data)
  File "/usr/local/miniconda3/envs/hy/lib/python3.8/site-packages/torch/utils/data/dataloader.py", line 1359, in _process_data
    data.reraise()
  File "/usr/local/miniconda3/envs/hy/lib/python3.8/site-packages/torch/_utils.py", line 543, in reraise
    raise exception
RuntimeError: Caught RuntimeError in DataLoader worker process 0.
Original Traceback (most recent call last):
  File "/usr/local/miniconda3/envs/hy/lib/python3.8/site-packages/torch/utils/data/_utils/worker.py", line 302, in _worker_loop
    data = fetcher.fetch(index)
  File "/usr/local/miniconda3/envs/hy/lib/python3.8/site-packages/torch/utils/data/_utils/fetch.py", line 58, in fetch
    data = [self.dataset[idx] for idx in possibly_batched_index]
  File "/usr/local/miniconda3/envs/hy/lib/python3.8/site-packages/torch/utils/data/_utils/fetch.py", line 58, in <listcomp>
    data = [self.dataset[idx] for idx in possibly_batched_index]
  File "/usr/local/miniconda3/envs/hy/lib/python3.8/site-packages/torch/utils/data/dataset.py", line 193, in __getitem__
    return tuple(tensor[index] for tensor in self.tensors)
  File "/usr/local/miniconda3/envs/hy/lib/python3.8/site-packages/torch/utils/data/dataset.py", line 193, in <genexpr>
    return tuple(tensor[index] for tensor in self.tensors)
RuntimeError: CUDA error: initialization error
CUDA kernel errors might be asynchronously reported at some other API call,so the stacktrace below might be incorrect.
For debugging consider passing CUDA_LAUNCH_BLOCKING=1.

